Workbook

Sheet START HERE
A2: Growing Forward Co.
A6: Monthly Budget Clarity Template
A7: Free Resource · growingforwardco.com
B11: Welcome!
B12: This template was built to give you clarity — not confusion — around your money. Whether you're just starting out or trying to get back on track, this sheet will show you exactly where every dollar is going.
B14: HOW TO USE THIS TEMPLATE
B15: 📋 Step 1 — Choose your sheet
B16: Use the tabs at the bottom to pick your budget style: • 'Single Paycheck' — one income stream per month • 'Dual Paycheck' — two pay cycles (bi-weekly, split income, etc.)
B18: ✏️ Step 2 — Fill in your expenses
B19: Enter your expense names and amounts in the white cells. Every total, yearly figure, and summary row will calculate automatically.
B21: 📅 Step 3 — Add your due dates
B22: Use the 'Due' column to note what day of the month each bill hits. This helps you plan which paycheck covers which expense.
B24: 💰 Step 4 — Enter your paycheck
B25: Scroll to the Summary section and enter your take-home pay. The Budget Remaining row will turn GREEN if you're in the clear, and RED if you're overspending — no guessing needed.
B27: 📊 Step 5 — Check the Overview tab
... B35: 💡 Yearly totals are eye-opening. That $20/mo subscription? $240/yr. Worth it?
A38: © Growing Forward Co. · growingforwardco.com · Share freely — please don't sell or modify without permission.

Sheet Dual Paycheck
A1: MONTHLY BUDGET TRACKER
A2: growingforwardco.com · Free Financial Clarity Template
A3: Expense | B3: Cycle A ($) | C3: Due | D3: Cycle B ($) | E3: Due | F3: Total/Mo | G3: Total/Yr
A4: EXPENSES
A5: Housing / Rent | F5: =IFERROR(IF(B5="",0,B5),0)+IFERROR(IF(D5="",0,D5),0) -> 0 | G5: =F5*12 -> 0
A6: Utilities | F6: =IFERROR(IF(B6="",0,B6),0)+IFERROR(IF(D6="",0,D6),0) -> 0 | G6: =F6*12 -> 0
A7: Groceries / Food | F7: =IFERROR(IF(B7="",0,B7),0)+IFERROR(IF(D7="",0,D7),0) -> 0 | G7: =F7*12 -> 0
A8: Gas / Transportation | F8: =IFERROR(IF(B8="",0,B8),0)+IFERROR(IF(D8="",0,D8),0) -> 0 | G8: =F8*12 -> 0
A9: Insurance | F9: =IFERROR(IF(B9="",0,B9),0)+IFERROR(IF(D9="",0,D9),0) -> 0 | G9: =F9*12 -> 0
A10: Medical / Health | F10: =IFERROR(IF(B10="",0,B10),0)+IFERROR(IF(D10="",0,D10),0) -> 0 | G10: =F10*12 -> 0
A11: Child / Pet Care | F11: =IFERROR(IF(B11="",0,B11),0)+IFERROR(IF(D11="",0,D11),0) -> 0 | G11: =F11*12 -> 0
A12: Other Expense | F12: =IFERROR(IF(B12="",0,B12),0)+IFERROR(IF(D12="",0,D12),0) -> 0 | G12: =F12*12 -> 0
A13: Expenses Total | B13: =SUM(B5:B12) -> 0 | D13: =SUM(D5:D12) -> 0 | F13: =SUM(F5:F12) -> 0 | G13: =SUM(G5:G12) -> 0
A14: SUBSCRIPTIONS & MEMBERSHIPS
A15: Streaming (Netflix, Hulu…) | F15: =IFERROR(IF(B15="",0,B15),0)+IFERROR(IF(D15="",0,D15),0) -> 0 | G15: =F15*12 -> 0
A16: Music / Podcasts | F16: =IFERROR(IF(B16="",0,B16),0)+IFERROR(IF(D16="",0,D16),0) -> 0 | G16: =F16*12 -> 0
A17: Cloud Storage | F17: =IFERROR(IF(B17="",0,B17),0)+IFERROR(IF(D17="",0,D17),0) -> 0 | G17: =F17*12 -> 0
A18: Software / Apps | F18: =IFERROR(IF(B18="",0,B18),0)+IFERROR(IF(D18="",0,D18),0) -> 0 | G18: =F18*12 -> 0
A19: Gym / Fitness | F19: =IFERROR(IF(B19="",0,B19),0)+IFERROR(IF(D19="",0,D19),0) -> 0 | G19: =F19*12 -> 0
A20: Other Subscription 1 | F20: =IFERROR(IF(B20="",0,B20),0)+IFERROR(IF(D20="",0,D20),0) -> 0 | G20: =F20*12 -> 0
A21: Other Subscription 2 | F21: =IFERROR(IF(B21="",0,B21),0)+IFERROR(IF(D21="",0,D21),0) -> 0 | G21: =F21*12 -> 0
A22: Subscriptions Total | B22: =SUM(B15:B21) -> 0 | D22: =SUM(D15:D21) -> 0 | F22: =SUM(F15:F21) -> 0 | G22: =SUM(G15:G21) -> 0
A23: CREDIT CARDS & LOANS
A24: Credit Card 1 | F24: =IFERROR(IF(B24="",0,B24),0)+IFERROR(IF(D24="",0,D24),0) -> 0 | G24: =F24*12 -> 0
A25: Credit Card 2 | F25: =IFERROR(IF(B25="",0,B25),0)+IFERROR(IF(D25="",0,D25),0) -> 0 | G25: =F25*12 -> 0
A26: Credit Card 3 | F26: =IFERROR(IF(B26="",0,B26),0)+IFERROR(IF(D26="",0,D26),0) -> 0 | G26: =F26*12 -> 0
A27: Auto Loan | F27: =IFERROR(IF(B27="",0,B27),0)+IFERROR(IF(D27="",0,D27),0) -> 0 | G27: =F27*12 -> 0
A28: Student Loan | F28: =IFERROR(IF(B28="",0,B28),0)+IFERROR(IF(D28="",0,D28),0) -> 0 | G28: =F28*12 -> 0
A29: Personal Loan | F29: =IFERROR(IF(B29="",0,B29),0)+IFERROR(IF(D29="",0,D29),0) -> 0 | G29: =F29*12 -> 0
A30: Other Debt 1 | F30: =IFERROR(IF(B30="",0,B30),0)+IFERROR(IF(D30="",0,D30),0) -> 0 | G30: =F30*12 -> 0
A31: Other Debt 2 | F31: =IFERROR(IF(B31="",0,B31),0)+IFERROR(IF(D31="",0,D31),0) -> 0 | G31: =F31*12 -> 0
A32: Credit & Loans Total | B32: =SUM(B24:B31) -> 0 | D32: =SUM(D24:D31) -> 0 | F32: =SUM(F24:F31) -> 0 | G32: =SUM(G24:G31) -> 0
A33: SAVINGS & INVESTMENTS
A34: Emergency Fund | F34: =IFERROR(IF(B34="",0,B34),0)+IFERROR(IF(D34="",0,D34),0) -> 0 | G34: =F34*12 -> 0
A35: Retirement (401k / IRA) | F35: =IFERROR(IF(B35="",0,B35),0)+IFERROR(IF(D35="",0,D35),0) -> 0 | G35: =F35*12 -> 0
A36: Investments | F36: =IFERROR(IF(B36="",0,B36),0)+IFERROR(IF(D36="",0,D36),0) -> 0 | G36: =F36*12 -> 0
A37: Other Savings | F37: =IFERROR(IF(B37="",0,B37),0)+IFERROR(IF(D37="",0,D37),0) -> 0 | G37: =F37*12 -> 0
A38: Savings Total | F38: =SUM(F34:F37) -> 0 | G38: =SUM(G34:G37) -> 0
A39: SUMMARY
A40: CYCLE A — Paycheck 1
...

Sheet Single Paycheck
A1: MONTHLY BUDGET TRACKER
A2: growingforwardco.com · Free Financial Clarity Template
A3: Expense | B3: Amount ($) | C3: Due Date | D3: Total/Mo | E3: Total/Yr
A4: EXPENSES
A5: Housing / Rent | D5: =IFERROR(IF(B5="",0,B5),0) -> 0 | E5: =D5*12 -> 0
A6: Utilities | D6: =IFERROR(IF(B6="",0,B6),0) -> 0 | E6: =D6*12 -> 0
A7: Groceries / Food | D7: =IFERROR(IF(B7="",0,B7),0) -> 0 | E7: =D7*12 -> 0
A8: Gas / Transportation | D8: =IFERROR(IF(B8="",0,B8),0) -> 0 | E8: =D8*12 -> 0
A9: Insurance | D9: =IFERROR(IF(B9="",0,B9),0) -> 0 | E9: =D9*12 -> 0
A10: Medical / Health | D10: =IFERROR(IF(B10="",0,B10),0) -> 0 | E10: =D10*12 -> 0
A11: Child / Pet Care | D11: =IFERROR(IF(B11="",0,B11),0) -> 0 | E11: =D11*12 -> 0
A12: Other Expense | D12: =IFERROR(IF(B12="",0,B12),0) -> 0 | E12: =D12*12 -> 0
A13: Expenses Total | B13: =SUM(B5:B12) -> 0 | D13: =SUM(D5:D12) -> 0 | E13: =SUM(E5:E12) -> 0
A14: SUBSCRIPTIONS & MEMBERSHIPS
A15: Streaming (Netflix, Hulu…) | D15: =IFERROR(IF(B15="",0,B15),0) -> 0 | E15: =D15*12 -> 0
A16: Music / Podcasts | D16: =IFERROR(IF(B16="",0,B16),0) -> 0 | E16: =D16*12 -> 0
A17: Cloud Storage | D17: =IFERROR(IF(B17="",0,B17),0) -> 0 | E17: =D17*12 -> 0
A18: Software / Apps | D18: =IFERROR(IF(B18="",0,B18),0) -> 0 | E18: =D18*12 -> 0
A19: Gym / Fitness | D19: =IFERROR(IF(B19="",0,B19),0) -> 0 | E19: =D19*12 -> 0
A20: Other Subscription 1 | D20: =IFERROR(IF(B20="",0,B20),0) -> 0 | E20: =D20*12 -> 0
A21: Other Subscription 2 | D21: =IFERROR(IF(B21="",0,B21),0) -> 0 | E21: =D21*12 -> 0
A22: Subscriptions Total | B22: =SUM(B15:B21) -> 0 | D22: =SUM(D15:D21) -> 0 | E22: =SUM(E15:E21) -> 0
A23: CREDIT CARDS & LOANS
A24: Credit Card 1 | D24: =IFERROR(IF(B24="",0,B24),0) -> 0 | E24: =D24*12 -> 0
A25: Credit Card 2 | D25: =IFERROR(IF(B25="",0,B25),0) -> 0 | E25: =D25*12 -> 0
A26: Credit Card 3 | D26: =IFERROR(IF(B26="",0,B26),0) -> 0 | E26: =D26*12 -> 0
A27: Auto Loan | D27: =IFERROR(IF(B27="",0,B27),0) -> 0 | E27: =D27*12 -> 0
A28: Student Loan | D28: =IFERROR(IF(B28="",0,B28),0) -> 0 | E28: =D28*12 -> 0
A29: Personal Loan | D29: =IFERROR(IF(B29="",0,B29),0) -> 0 | E29: =D29*12 -> 0
A30: Other Debt 1 | D30: =IFERROR(IF(B30="",0,B30),0) -> 0 | E30: =D30*12 -> 0
A31: Other Debt 2 | D31: =IFERROR(IF(B31="",0,B31),0) -> 0 | E31: =D31*12 -> 0
A32: Credit & Loans Total | B32: =SUM(B24:B31) -> 0 | D32: =SUM(D24:D31) -> 0 | E32: =SUM(E24:E31) -> 0
A33: SAVINGS & INVESTMENTS
A34: Emergency Fund | D34: =IFERROR(IF(B34="",0,B34),0) -> 0 | E34: =D34*12 -> 0
A35: Retirement (401k / IRA) | D35: =IFERROR(IF(B35="",0,B35),0) -> 0 | E35: =D35*12 -> 0
A36: Investments | D36: =IFERROR(IF(B36="",0,B36),0) -> 0 | E36: =D36*12 -> 0
A37: Other Savings | D37: =IFERROR(IF(B37="",0,B37),0) -> 0 | E37: =D37*12 -> 0
A38: Savings Total | D38: =SUM(D34:D37) -> 0 | E38: =SUM(E34:E37) -> 0
A39: SUMMARY
A40: Monthly Paycheck / Income | D40: 0 | E40: =D40*12 -> 0
...

Sheet Overview
A1: BUDGET OVERVIEW
A2: Monthly spending breakdown · Dual Paycheck sheet
A3: Category | B3: Monthly Total
A4: Expenses | B4: ='Dual Paycheck'!F13 -> 0
A5: Subscriptions | B5: ='Dual Paycheck'!F22 -> 0
A6: Credit & Loans | B6: ='Dual Paycheck'!F32 -> 0
A7: Savings | B7: ='Dual Paycheck'!F38 -> 0
A8: Remaining | B8: ='Dual Paycheck'!F51 -> 0
